<?xml version="1.0"?>
<robot name="my_2wd_robot" xmlns:xacro="http://www.ros.org/wiki/xacro">

  <!-- Constants -->
  <xacro:property name="wheel_radius" value="0.033"/>  <!-- 33mm = 0.033m -->
  <xacro:property name="wheel_width" value="0.026"/>   <!-- 26mm -->
  <xacro:property name="wheel_base" value="0.15"/>     <!-- 150mm between wheels -->
  <xacro:property name="chassis_length" value="0.20"/>
  <xacro:property name="chassis_width" value="0.15"/>
  <xacro:property name="chassis_height" value="0.05"/>

  <!-- Base Link (Chassis) -->
  <link name="base_link">
    <visual>
      <geometry>
        <box size="${chassis_length} ${chassis_width} ${chassis_height}"/>
      </geometry>
      <material name="blue">
        <color rgba="0 0 0.8 1"/>
      </material>
    </visual>
    <collision>
      <geometry>
        <box size="${chassis_length} ${chassis_width} ${chassis_height}"/>
      </geometry>
    </collision>
    <inertial>
      <mass value="1.0"/>
      <inertia ixx="0.01" ixy="0.0" ixz="0.0" 
               iyy="0.01" iyz="0.0" izz="0.01"/>
    </inertial>
  </link>

  <!-- Left Wheel -->
  <link name="left_wheel">
    <visual>
      <geometry>
        <cylinder radius="${wheel_radius}" length="${wheel_width}"/>
      </geometry>
      <material name="black">
        <color rgba="0.2 0.2 0.2 1"/>
      </material>
    </visual>
    <collision>
      <geometry>
        <cylinder radius="${wheel_radius}" length="${wheel_width}"/>
      </geometry>
    </collision>
    <inertial>
      <mass value="0.1"/>
      <inertia ixx="0.0001" ixy="0.0" ixz="0.0" 
               iyy="0.0001" iyz="0.0" izz="0.0001"/>
    </inertial>
  </link>

  <!-- Left Wheel Joint -->
  <joint name="left_wheel_joint" type="continuous">
    <parent link="base_link"/>
    <child link="left_wheel"/>
    <origin xyz="0 ${wheel_base/2} 0" rpy="-1.5707 0 0"/>
    <axis xyz="0 0 1"/>
  </joint>

  <!-- Right Wheel -->
  <link name="right_wheel">
    <visual>
      <geometry>
        <cylinder radius="${wheel_radius}" length="${wheel_width}"/>
      </geometry>
      <material name="black">
        <color rgba="0.2 0.2 0.2 1"/>
      </material>
    </visual>
    <collision>
      <geometry>
        <cylinder radius="${wheel_radius}" length="${wheel_width}"/>
      </geometry>
    </collision>
    <inertial>
      <mass value="0.1"/>
      <inertia ixx="0.0001" ixy="0.0" ixz="0.0" 
               iyy="0.0001" iyz="0.0" izz="0.0001"/>
    </inertial>
  </link>

  <!-- Right Wheel Joint -->
  <joint name="right_wheel_joint" type="continuous">
    <parent link="base_link"/>
    <child link="right_wheel"/>
    <origin xyz="0 ${-wheel_base/2} 0" rpy="-1.5707 0 0"/>
    <axis xyz="0 0 1"/>
  </joint>

  <!-- Ball Caster (simplified as sphere) -->
  <link name="caster">
    <visual>
      <geometry>
        <sphere radius="0.015"/>  <!-- 15mm ball -->
      </geometry>
      <material name="white">
        <color rgba="1 1 1 1"/>
      </material>
    </visual>
    <collision>
      <geometry>
        <sphere radius="0.015"/>
      </geometry>
    </collision>
    <inertial>
      <mass value="0.01"/>
      <inertia ixx="0.00001" ixy="0.0" ixz="0.0" 
               iyy="0.00001" iyz="0.0" izz="0.00001"/>
    </inertial>
  </link>

  <!-- Caster Joint -->
  <joint name="caster_joint" type="fixed">
    <parent link="base_link"/>
    <child link="caster"/>
    <origin xyz="-0.08 0 -0.02" rpy="0 0 0"/>
  </joint>

  <!-- IMU Link -->
  <link name="imu_link">
    <visual>
      <geometry>
        <box size="0.02 0.02 0.01"/>
      </geometry>
      <material name="green">
        <color rgba="0 0.8 0 1"/>
      </material>
    </visual>
  </link>

  <!-- IMU Joint -->
  <joint name="imu_joint" type="fixed">
    <parent link="base_link"/>
    <child link="imu_link"/>
    <origin xyz="0 0 0.03" rpy="0 0 0"/>
  </joint>

  <!-- ========================================= -->
  <!-- GAZEBO PLUGINS (This is where magic happens!) -->
  <!-- ========================================= -->

  <!-- Differential Drive Plugin (Controls wheels like real motors) -->
  <gazebo>
    <plugin filename="libgz-sim-diff-drive-system.so" name="gz::sim::systems::DiffDrive">
      
      <!-- Wheel joints -->
      <left_joint>left_wheel_joint</left_joint>
      <right_joint>right_wheel_joint</right_joint>
      
      <!-- Kinematics -->
      <wheel_separation>${wheel_base}</wheel_separation>
      <wheel_radius>${wheel_radius}</wheel_radius>
      
      <!-- Topic (robot will subscribe to /model/my_robot/cmd_vel) -->
      <topic>/model/my_robot/cmd_vel</topic>

      <!-- Odometry -->
      <odom_topic>/model/my_robot/odometry</odom_topic>
      <odom_publish_frequency>50</odom_publish_frequency>

      <!-- TF frames -->
      <frame_id>odom</frame_id>
      <child_frame_id>base_link</child_frame_id>
    
    </plugin>
  </gazebo>

  <!-- IMU Sensor Plugin (Simulates MPU6050) -->
  <gazebo reference="imu_link">
    <sensor name="imu_sensor" type="imu">
      <always_on>1</always_on>
      <update_rate>100</update_rate>
      <visualize>true</visualize>
      <topic>imu</topic>
      <enable_metrics>false</enable_metrics>
    </sensor>
  </gazebo>

  <!-- Joint State Publisher (Publishes wheel positions = encoders!) -->
  <gazebo>
    <plugin filename="gz-sim-joint-state-publisher-system" 
            name="gz::sim::systems::JointStatePublisher">
      <joint_name>left_wheel_joint</joint_name>
      <joint_name>right_wheel_joint</joint_name>
      <update_rate>50</update_rate>
    </plugin>
  </gazebo>

  <!-- Material colors for Gazebo -->
  <gazebo reference="base_link">
    <material>
      <ambient>0 0 0.8 1</ambient>
      <diffuse>0 0 0.8 1</diffuse>
    </material>
  </gazebo>
  
  <gazebo reference="left_wheel">
    <material>
      <ambient>0.2 0.2 0.2 1</ambient>
      <diffuse>0.2 0.2 0.2 1</diffuse>
    </material>
  </gazebo>
  
  <gazebo reference="right_wheel">
    <material>
      <ambient>0.2 0.2 0.2 1</ambient>
      <diffuse>0.2 0.2 0.2 1</diffuse>
    </material>
  </gazebo>
  
  <gazebo reference="caster">
    <material>
      <ambient>1 1 1 1</ambient>
      <diffuse>1 1 1 1</diffuse>
    </material>
  </gazebo>

</robot>